<?xml version="1.0"?>
<robot name="rocker" xmlns:xacro="http://www.ros.org/wiki/xacro">

  <!-- Import wheels -->
  <xacro:include filename="$(find rb_theron_description)/urdf/wheels/rubber_wheel_150.urdf.xacro" />

  <!-- Import casters -->
  <xacro:include filename="$(find rb_theron_description)/urdf/wheels/castor.urdf.xacro" />
	
  <xacro:property name="M_PI" value="3.1415926535897931" />

  <!-- Caster support parameters -->
  <xacro:property name="rocker_support_mass" value="1.5" /> <!-- in kg-->

  <xacro:macro name="cylinder_inertia" params="m r h">
    <inertia  ixx="${m*(3*r*r+h*h)/12}" ixy = "0" ixz = "0"
              iyy="${m*(3*r*r+h*h)/12}" iyz = "0"
              izz="${m*r*r/2}" /> 
  </xacro:macro>
 
  <xacro:macro name="rocker" params="prefix parent *origin reflect hq">
	 
	<!--ROCKER BOGIE SUPPORT -->
	<!--joint name="${prefix}joint_support" type="continuous">
      <parent link="${parent}"/>
      <child link="${prefix}support"/>
      <insert_block name="origin" />
      <axis xyz="0 1 0" rpy="0 0 ${M_PI}" />
      <limit effort="100" velocity="100"/>
      <joint_properties damping="0.1" friction="0.1"/>
	</joint -->

	<joint name="${prefix}joint_rsupport" type="revolute">
      <parent link="${parent}"/>
      <child link="${prefix}rsupport"/>
      <insert_block name="origin" />
      <axis xyz="0 1 0" rpy="0 0 ${M_PI}" />
      <limit lower="-0.5" upper="0.5" effort="100" velocity="100"/>
      <joint_properties damping="0.1" friction="0.1"/>
	</joint>
	
	
	
	<link name="${prefix}rsupport">
      <visual>
        <origin xyz="0 0 0" rpy="0 0 0" />
          <xacro:if value="${reflect}">
            <geometry>     
	          <mesh filename="package://rb_theron_description/meshes/rocker/mcq_prototype_rocker_r.dae" />
            </geometry>         
          </xacro:if>
          <xacro:unless value="${reflect}">
            <geometry>     
              <mesh filename="package://rb_theron_description/meshes/rocker/mcq_prototype_rocker_l.dae" />
            </geometry>			  
		  </xacro:unless>
      </visual>
      <collision>
        <origin xyz="0 0 0" rpy="0 0 0" />
          <xacro:if value="${reflect}">
            <geometry>     
	          <mesh filename="package://rb_theron_description/meshes/rocker/mcq_prototype_rocker_r.dae" />
            </geometry> 
          </xacro:if>
          <xacro:unless value="${reflect}">
            <geometry>     
              <mesh filename="package://rb_theron_description/meshes/rocker/mcq_prototype_rocker_l.dae" />
            </geometry>			  
		  </xacro:unless>
      </collision>    
      <inertial>
        <mass value="${rocker_support_mass}" />
        <origin xyz="0 0 0" />
        <cylinder_inertia  m="${rocker_support_mass}" r="0.010" h="0.010" />  <!--Check these values -->
      </inertial>
	</link> 
  
	<!-- Transmission is important to link the joints and the controller -->
	<transmission name="${prefix}rsupport_joint_trans">
	  <type>transmission_interface/SimpleTransmission</type>
	  <joint name="${prefix}joint_rsupport">
		  <hardwareInterface>hardware_interface/EffortJointInterface</hardwareInterface>
	  </joint>
	  <actuator name="${prefix}rsupport_joint_motor">
		<mechanicalReduction>1</mechanicalReduction>
		<motorTorqueConstant>1</motorTorqueConstant>
	  </actuator>
	</transmission>
    
	<!-- Flag to select the high or low quality model -->
	<xacro:property name="hq" value="true" />
	    
    <xacro:property name="wheel_offset_x" value="-0.1175" />
    <xacro:if value="${reflect}">    
         <xacro:property name="wheel_offset_y" value="-0.079" />
    </xacro:if>
    <xacro:unless value="${reflect}">
		 <xacro:property name="wheel_offset_y" value="0.079" />
    </xacro:unless>
        
    <xacro:property name="wheel_offset_z" value="-0.0428" />

	<!-- xacro:rubber_wheel prefix="$(arg prefix)wheel" parent="$(arg prefix)support" reflect="true" hq="${hq}">
		<origin xyz="${wheel_offset_x} ${wheel_offset_y} ${wheel_offset_z}" rpy="0 0 0"/>
	</xacro:rubber_wheel -->
		
	<xacro:rubber_wheel prefix="${prefix}" parent="${prefix}rsupport" reflect="true" hq="${hq}">
		<origin xyz="${wheel_offset_x} ${wheel_offset_y} ${wheel_offset_z}" rpy="0 0 0"/>
	</xacro:rubber_wheel>

    <xacro:property name="caster_offset_x" value="0.1175" />
    <xacro:property name="caster_offset_y" value="0.010" />
    <xacro:property name="caster_offset_z" value="0.002" />
														
	<!-- xacro:caster prefix="$(arg prefix)left" parent="$(arg prefix)support" hq="${hq}">
		<origin xyz="${caster_offset_x} ${caster_offset_y} ${caster_offset_z}" rpy="0 0 0"/>
	</xacro:caster -->
	
	<xacro:caster prefix="${prefix}castor" parent="${prefix}rsupport" hq="${hq}">
		<origin xyz="${caster_offset_x} ${caster_offset_y} ${caster_offset_z}" rpy="0 0 0"/>
	</xacro:caster>

    <!-- gazebo reference="${prefix}support">
			<mu1 value="5.0"/>
			<mu2 value="0.5"/>
			<kp value="10000000.0" />
			<kd value="1.0" />
			<fdir1 value="1 0 0"/>
      <turnGravityOff>false</turnGravityOff>
    </gazebo>
    
     <gazebo reference="${prefix}_wheel">
			<mu1 value="5.0"/>
			<mu2 value="0.5"/>
			<kp value="10000000.0" />
			<kd value="1.0" />
			<fdir1 value="1 0 0"/>
      <turnGravityOff>false</turnGravityOff>
    </gazebo --> 
 </xacro:macro> 

</robot>
