<?xml version="1.0" encoding="utf-8"?>
<!-- =================================================================================== -->
<!-- |    This document was autogenerated by xacro from rb_theron_mcq.urdf.xacro       | -->
<!-- |    EDITING THIS FILE BY HAND IS NOT RECOMMENDED                                 | -->
<!-- =================================================================================== -->
<robot name="rb_theron">
  <!-- ***************** -->
  <!-- Imported elements -->
  <!-- ***************** -->
  <!-- First we import all posible elements defined in the urdf.xacro files. All these elements are defined as macro:xacros -->
  <!-- in kg-->
  <!-- in kg-->
  <!-- in kg-->
  <!-- in kg-->
  <!-- in kg-->
  <!-- in kg-->
  <!-- in kg-->
  <!-- source en.wikipedia.org/wiki/List_of_moments_of_inertia-->
  <!-- This file unifies all sensors that can be used on simulation, defined as xacro:macros -->
  <!-- Includes -->
  <!-- *************** -->
  <!-- Robots Elements -->
  <!-- *************** -->
  <!-- Here we create the robot elements using the xacro:macros imported at the beggining of this file -->
  <!-- this property is for the chassis -->
  <!-- xacro:property name="wheel_width" value="0.150" / -->
  <link name="robot_base_footprint">
    <visual>
      <origin rpy="0 0 0" xyz="0 0 0"/>
      <geometry>
        <box size="0.001 0.001 0.001"/>
      </geometry>
    </visual>
  </link>
  <joint name="robot_base_footprint_joint" type="fixed">
    <origin rpy="0 0 0" xyz="0 0 0.0606"/>
    <parent link="robot_base_footprint"/>
    <child link="robot_base_link"/>
  </joint>
  <!-- BASE_LINK -->
  <link name="robot_base_link">
    <inertial>
      <mass value="50.0"/>
      <origin xyz="-0.120 0 0"/>
      <inertia ixx="2.01041666667" ixy="0" ixz="0" iyy="2.55208333333" iyz="0" izz="2.55208333333"/>
    </inertial>
    <visual>
      <origin rpy="0 0 0" xyz="0 0 0"/>
      <geometry>
        <mesh filename="package://rb_theron_description/meshes/bases/theron_base.stl"/>
      </geometry>
      <material name="darkgrey">
        <color rgba="0.1 0.1 0.1 1"/>
      </material>
    </visual>
    <collision>
      <origin rpy="0 0 0 " xyz="0 0 0"/>
      <geometry>
        <!--box size="0.390 0.240 0.165"/-->
        <mesh filename="package://rb_theron_description/meshes/bases/theron_base.stl"/>
      </geometry>
    </collision>
  </link>
  <!-- <link name="${prefix}bottom_cover_link">
      <inertial>
        <mass value="2.0" />
        <origin xyz="0 0 0" />
	    <xacro:box_inertia_robot m="2" x="0.700" y="0.600" z="0.350"/>
      </inertial>
      <visual>
        <origin xyz="0 0 0" rpy="0 0 0" />
        <xacro:if value="${hq}">
          <geometry>
            <mesh filename="package://rb_theron_description/meshes/bases/mcq_prototype_bottom_cover.dae"/>
          </geometry>
        </xacro:if>
        <xacro:unless value="${hq}">
          <geometry>
            <box size="0.700 0.600 0.350"/>
          </geometry>
        </xacro:unless>
        <material name="darkgrey">
          <color rgba="0.1 0.1 0.1 1"/>
        </material>
      </visual>
      <collision>
        <origin xyz="0 0 0" rpy="0 0 0 " />
        <geometry>
          <mesh filename="package://rb_theron_description/meshes/bases/mcq_prototype_bottom_cover.dae"/>
        </geometry>
      </collision>
    </link> -->
  <!-- <joint name="${prefix}bottom_cover_joint" type="fixed">
       <origin rpy="0 0 0" xyz="0 0 0"/>
       <parent link="${prefix}base_link"/>
       <child link="${prefix}bottom_cover_link"/>
    </joint> -->
  <!-- DOCKING CONTACTS -->
  <!--joint name="${prefix}base_docking_joint" type="fixed">
      <origin xyz="0.030 0.000 0.068" rpy="0 0 0 " />
      <parent link="${prefix}front_cover_link"/>
      <child link="${prefix}base_docking_contact_link" />
    </joint-->
  <!-- DOCKING LINK -->
  <!--link name="${prefix}base_docking_contact_link" /-->
  <gazebo>
    <plugin filename="libgazebo_ros_control.so" name="ros_control">
      <!--robotNamespace>/robot</robotNamespace-->
      <robotParam>robot/robot_description</robotParam>
      <controlPeriod>0.001</controlPeriod>
      <robotSimType>gazebo_ros_control/DefaultRobotHWSim</robotSimType>
      <legacyModeNS>true</legacyModeNS>
    </plugin>
  </gazebo>
  <gazebo reference="robot_base_footprint">
    <material>Gazebo/Green</material>
  </gazebo>
  <gazebo reference="robot_base_link">
    <material>Gazebo/Grey</material>
  </gazebo>
  <gazebo reference="robot_front_cover_link">
    <material>Gazebo/Black</material>
  </gazebo>
  <!--ROCKER BOGIE SUPPORT -->
  <!--joint name="${prefix}joint_support" type="continuous">
      <parent link="${parent}"/>
      <child link="${prefix}support"/>
      <insert_block name="origin" />
      <axis xyz="0 1 0" rpy="0 0 ${M_PI}" />
      <limit effort="100" velocity="100"/>
      <joint_properties damping="0.1" friction="0.1"/>
	</joint -->
  <joint name="robot_rightjoint_rsupport" type="revolute">
    <parent link="robot_base_link"/>
    <child link="robot_rightrsupport"/>
    <origin rpy="0 0 0" xyz="0.1175 -0.1725 0.0428"/>
    <axis rpy="0 0 3.14159265359" xyz="0 1 0"/>
    <limit effort="100" lower="-0.5" upper="0.5" velocity="100"/>
    <joint_properties damping="0.1" friction="0.1"/>
  </joint>
  <link name="robot_rightrsupport">
    <visual>
      <origin rpy="0 0 0" xyz="0 0 0"/>
      <geometry>
        <mesh filename="package://rb_theron_description/meshes/rocker/mcq_prototype_rocker_r.dae"/>
      </geometry>
    </visual>
    <collision>
      <origin rpy="0 0 0" xyz="0 0 0"/>
      <geometry>
        <mesh filename="package://rb_theron_description/meshes/rocker/mcq_prototype_rocker_r.dae"/>
      </geometry>
    </collision>
    <inertial>
      <mass value="1.5"/>
      <origin xyz="0 0 0"/>
      <inertia ixx="5e-05" ixy="0" ixz="0" iyy="5e-05" iyz="0" izz="7.5e-05"/>
      <!--Check these values -->
    </inertial>
  </link>
  <!-- Transmission is important to link the joints and the controller -->
  <transmission name="robot_rightrsupport_joint_trans">
    <type>transmission_interface/SimpleTransmission</type>
    <joint name="robot_rightjoint_rsupport">
      <hardwareInterface>hardware_interface/EffortJointInterface</hardwareInterface>
    </joint>
    <actuator name="robot_rightrsupport_joint_motor">
      <mechanicalReduction>1</mechanicalReduction>
      <motorTorqueConstant>1</motorTorqueConstant>
    </actuator>
  </transmission>
  <!-- xacro:rubber_wheel prefix="$(arg prefix)wheel" parent="$(arg prefix)support" reflect="true" hq="${hq}">
		<origin xyz="${wheel_offset_x} ${wheel_offset_y} ${wheel_offset_z}" rpy="0 0 0"/>
	</xacro:rubber_wheel -->
  <!--WHEEL TIRE -->
  <joint name="robot_right_wheel_joint" type="continuous">
    <parent link="robot_rightrsupport"/>
    <child link="robot_right_wheel_link"/>
    <origin rpy="0 0 0" xyz="-0.1175 -0.079 -0.0428"/>
    <axis rpy="0 0 0" xyz="0 1 0"/>
    <limit effort="100" velocity="100"/>
    <joint_properties damping="0.0" friction="0.0"/>
  </joint>
  <link name="robot_right_wheel_link">
    <visual>
      <!-- HIGH RESOLUTION WHEELS -->
      <!-- LOW RESOLUTION WHEELS -->
      <origin rpy="1.57079632679 0 0" xyz="0 0 0"/>
      <geometry>
        <cylinder length="0.025" radius="0.0756"/>
      </geometry>
    </visual>
    <collision>
      <origin rpy="1.57079632679 0 0" xyz="0 0 0"/>
      <geometry>
        <cylinder length="0.025" radius="0.0756"/>
      </geometry>
    </collision>
    <inertial>
      <mass value="0.25"/>
      <origin xyz="0 0 0"/>
      <inertia ixx="0.000370230833333" ixy="0" ixz="0" iyy="0.000370230833333" iyz="0" izz="0.00071442"/>
    </inertial>
  </link>
  <!-- Transmission is important to link the joints and the controller (see rb_theron_control/config/rb_theron_control.yaml)-->
  <transmission name="robot_right_wheel_joint_trans">
    <type>transmission_interface/SimpleTransmission</type>
    <joint name="robot_right_wheel_joint">
      <!-- for the gazebo plugin -->
      <!--hardwareInterface>EffortJointInterface</hardwareInterface-->
      <!-- for ros control controller -->
      <hardwareInterface>hardware_interface/VelocityJointInterface</hardwareInterface>
    </joint>
    <actuator name="robot_right_wheel_joint_motor">
      <mechanicalReduction>1</mechanicalReduction>
      <motorTorqueConstant>20</motorTorqueConstant>
    </actuator>
  </transmission>
  <gazebo reference="robot_right_wheel_link">
    <!-- mu1 value="5.0"/>
			<mu2 value="0.5"/>
			<kp value="10000000.0" />
			<kd value="1.0" />
			<fdir1 value="1 0 0"/>
			<material>Gazebo/Yellow</material>
			<turnGravityOff>false</turnGravityOff -->
    <!-- mu1 value="5.0"/>
			<mu2 value="0.5"/ -->
    <mu1 value="100.0"/>
    <mu2 value="100.0"/>
    <!-- kp value="100000.0" / -->
    <kp value="500000.0"/>
    <kd value="1.0"/>
    <!-- fdir1 value="1 0 0"/ -->
    <material>Gazebo/Yellow</material>
    <turnGravityOff>false</turnGravityOff>
    <!--kp>500000.0</kp>
			<kd>10.0</kd>
			<mu1>10</mu1>
			<mu2>10</mu2>
			<fdir1>1 0 0</fdir1-->
    <!--minDepth>0.001</minDepth-->
    <!--material>Gazebo/Black</material-->
    <!--mu1 value="10"/>
			<mu2 value="5"/>
			<kp value="500000.0" />
			<kd value="10.0" />
			<fdir1 value="1 0 0"/>
			<material>Gazebo/Yellow</material>
			<turnGravityOff>false</turnGravityOff-->
  </gazebo>
  <!--gazebo reference="${name}_wheel_link">
			<kp>500000.0</kp>
			<kd>10.0</kd>
			<mu1>10</mu1>
			<mu2>10</mu2>
			<fdir1>1 0 0</fdir1>
			<maxVel>1.0</maxVel>
			<minDepth>0.003</minDepth>
			<material>Gazebo/Yellow</material>
			<turnGravityOff>false</turnGravityOff>
			<implicitSpringDamper>1</implicitSpringDamper>
		</gazebo-->
  <!-- xacro:caster prefix="$(arg prefix)left" parent="$(arg prefix)support" hq="${hq}">
		<origin xyz="${caster_offset_x} ${caster_offset_y} ${caster_offset_z}" rpy="0 0 0"/>
	</xacro:caster -->
  <!--CASTER SUPPORT -->
  <joint name="robot_rightcastorjoint_support" type="continuous">
    <parent link="robot_rightrsupport"/>
    <child link="robot_rightcastorsupport"/>
    <origin rpy="0 0 0" xyz="0.1175 0.01 0.002"/>
    <axis rpy="0 3.14159265359 0" xyz="0 0 1"/>
    <limit effort="100" velocity="100"/>
    <!-- joint_properties damping="1.5" friction="1.5"/ -->
    <dynamics damping="0" friction="0.01"/>
  </joint>
  <link name="robot_rightcastorsupport">
    <visual>
      <origin rpy="0 0 0" xyz="0 0 0"/>
      <geometry>
        <mesh filename="package://rb_theron_description/meshes/wheels/mcq_prototype_base_castor.dae"/>
      </geometry>
    </visual>
    <collision>
      <origin rpy="0 0 0" xyz="0 0 0"/>
      <geometry>
        <mesh filename="package://rb_theron_description/meshes/wheels/mcq_prototype_base_castor.dae"/>
      </geometry>
    </collision>
    <inertial>
      <mass value="1.5"/>
      <origin xyz="0 0 0"/>
      <inertia ixx="5e-05" ixy="0" ixz="0" iyy="5e-05" iyz="0" izz="7.5e-05"/>
      <!--Check these values -->
    </inertial>
  </link>
  <joint name="robot_rightcastorjoint_wheel" type="continuous">
    <parent link="robot_rightcastorsupport"/>
    <child link="robot_rightcastorwheel"/>
    <origin rpy="0 0 0" xyz="-0.033 0.0 -0.071"/>
    <axis rpy="0 0 0" xyz="0 1 0"/>
    <limit effort="100" velocity="100"/>
    <joint_properties damping="0.1" friction="0.1"/>
  </joint>
  <link name="robot_rightcastorwheel">
    <visual>
      <!-- HIGH RESOLUTION WHEELS -->
      <!-- xacro:if value="${hq}">
          <origin xyz="0 0 0" rpy="0 0 0" />
          <geometry>     
		<mesh filename="package://rb_theron_description/meshes/wheels/mcq_prototype_castor_wheel.dae" />
          </geometry>         
        </xacro:if -->
      <!-- LOW RESOLUTION WHEELS -->
      <!-- xacro:unless value="${hq}" -->
      <origin rpy="1.57079632679 0 0" xyz="0 0 0"/>
      <geometry>
        <cylinder length="0.025" radius="0.05"/>
        <!-- sphere radius="${caster_radius}"/ -->
      </geometry>
      <!-- /xacro:unless -->
    </visual>
    <collision>
      <origin rpy="1.57079632679 0 0" xyz="0 0 0"/>
      <!-- origin xyz="0 0 0" rpy="0 0 0" / -->
      <geometry>
        <!-- mesh filename="package://rb_theron_description/meshes/wheels/mcq_prototype_castor_wheel.dae" / -->
        <cylinder length="0.025" radius="0.05"/>
        <!-- sphere radius="${caster_radius}"/ -->
      </geometry>
      <surface>
        <bounce restitution_coefficient="1"/>
      </surface>
    </collision>
    <inertial>
      <mass value="0.25"/>
      <origin xyz="0 0 0"/>
      <inertia ixx="0.000169270833333" ixy="0" ixz="0" iyy="0.000169270833333" iyz="0" izz="0.0003125"/>
    </inertial>
  </link>
  <!-- Transmission is important to link the joints and the controller -->
  <transmission name="robot_rightcastorsupport_joint_trans">
    <type>transmission_interface/SimpleTransmission</type>
    <joint name="robot_rightcastorjoint_support">
      <hardwareInterface>hardware_interface/EffortJointInterface</hardwareInterface>
    </joint>
    <actuator name="robot_rightcastorsupport_joint_motor">
      <mechanicalReduction>1</mechanicalReduction>
      <motorTorqueConstant>1</motorTorqueConstant>
    </actuator>
  </transmission>
  <transmission name="robot_rightcastorwheel_joint_trans">
    <type>transmission_interface/SimpleTransmission</type>
    <joint name="robot_rightcastorjoint_wheel">
      <hardwareInterface>hardware_interface/EffortJointInterface</hardwareInterface>
    </joint>
    <actuator name="robot_rightcastorwheel_joint_motor">
      <mechanicalReduction>1</mechanicalReduction>
      <motorTorqueConstant>1</motorTorqueConstant>
    </actuator>
  </transmission>
  <!-- gazebo reference="${prefix}support">
			<mu1 value="5.0"/>
			<mu2 value="0.5"/>
			<kp value="10000000.0" />
			<kd value="1.0" />
			<fdir1 value="1 0 0"/>
      <turnGravityOff>false</turnGravityOff>
    </gazebo -->
  <gazebo reference="robot_rightcastor_wheel">
    <mu1 value="100.0"/>
    <mu2 value="100.0"/>
    <!-- kp value="10000000.0" / -->
    <kp value="100000.0"/>
    <kd value="100.0"/>
    <!-- fdir1 value="1 0 0"/ -->
    <material>Gazebo/Black</material>
    <turnGravityOff>false</turnGravityOff>
  </gazebo>
  <!-- gazebo reference="${prefix}support">
			<mu1 value="5.0"/>
			<mu2 value="0.5"/>
			<kp value="10000000.0" />
			<kd value="1.0" />
			<fdir1 value="1 0 0"/>
      <turnGravityOff>false</turnGravityOff>
    </gazebo>
    
     <gazebo reference="${prefix}_wheel">
			<mu1 value="5.0"/>
			<mu2 value="0.5"/>
			<kp value="10000000.0" />
			<kd value="1.0" />
			<fdir1 value="1 0 0"/>
      <turnGravityOff>false</turnGravityOff>
    </gazebo -->
  <!--ROCKER BOGIE SUPPORT -->
  <!--joint name="${prefix}joint_support" type="continuous">
      <parent link="${parent}"/>
      <child link="${prefix}support"/>
      <insert_block name="origin" />
      <axis xyz="0 1 0" rpy="0 0 ${M_PI}" />
      <limit effort="100" velocity="100"/>
      <joint_properties damping="0.1" friction="0.1"/>
	</joint -->
  <joint name="robot_leftjoint_rsupport" type="revolute">
    <parent link="robot_base_link"/>
    <child link="robot_leftrsupport"/>
    <origin rpy="0 0 0" xyz="0.1175 0.1725 0.0428"/>
    <axis rpy="0 0 3.14159265359" xyz="0 1 0"/>
    <limit effort="100" lower="-0.5" upper="0.5" velocity="100"/>
    <joint_properties damping="0.1" friction="0.1"/>
  </joint>
  <link name="robot_leftrsupport">
    <visual>
      <origin rpy="0 0 0" xyz="0 0 0"/>
      <geometry>
        <mesh filename="package://rb_theron_description/meshes/rocker/mcq_prototype_rocker_l.dae"/>
      </geometry>
    </visual>
    <collision>
      <origin rpy="0 0 0" xyz="0 0 0"/>
      <geometry>
        <mesh filename="package://rb_theron_description/meshes/rocker/mcq_prototype_rocker_l.dae"/>
      </geometry>
    </collision>
    <inertial>
      <mass value="1.5"/>
      <origin xyz="0 0 0"/>
      <inertia ixx="5e-05" ixy="0" ixz="0" iyy="5e-05" iyz="0" izz="7.5e-05"/>
      <!--Check these values -->
    </inertial>
  </link>
  <!-- Transmission is important to link the joints and the controller -->
  <transmission name="robot_leftrsupport_joint_trans">
    <type>transmission_interface/SimpleTransmission</type>
    <joint name="robot_leftjoint_rsupport">
      <hardwareInterface>hardware_interface/EffortJointInterface</hardwareInterface>
    </joint>
    <actuator name="robot_leftrsupport_joint_motor">
      <mechanicalReduction>1</mechanicalReduction>
      <motorTorqueConstant>1</motorTorqueConstant>
    </actuator>
  </transmission>
  <!-- xacro:rubber_wheel prefix="$(arg prefix)wheel" parent="$(arg prefix)support" reflect="true" hq="${hq}">
		<origin xyz="${wheel_offset_x} ${wheel_offset_y} ${wheel_offset_z}" rpy="0 0 0"/>
	</xacro:rubber_wheel -->
  <!--WHEEL TIRE -->
  <joint name="robot_left_wheel_joint" type="continuous">
    <parent link="robot_leftrsupport"/>
    <child link="robot_left_wheel_link"/>
    <origin rpy="0 0 0" xyz="-0.1175 0.079 -0.0428"/>
    <axis rpy="0 0 0" xyz="0 1 0"/>
    <limit effort="100" velocity="100"/>
    <joint_properties damping="0.0" friction="0.0"/>
  </joint>
  <link name="robot_left_wheel_link">
    <visual>
      <!-- HIGH RESOLUTION WHEELS -->
      <!-- LOW RESOLUTION WHEELS -->
      <origin rpy="1.57079632679 0 0" xyz="0 0 0"/>
      <geometry>
        <cylinder length="0.025" radius="0.0756"/>
      </geometry>
    </visual>
    <collision>
      <origin rpy="1.57079632679 0 0" xyz="0 0 0"/>
      <geometry>
        <cylinder length="0.025" radius="0.0756"/>
      </geometry>
    </collision>
    <inertial>
      <mass value="0.25"/>
      <origin xyz="0 0 0"/>
      <inertia ixx="0.000370230833333" ixy="0" ixz="0" iyy="0.000370230833333" iyz="0" izz="0.00071442"/>
    </inertial>
  </link>
  <!-- Transmission is important to link the joints and the controller (see rb_theron_control/config/rb_theron_control.yaml)-->
  <transmission name="robot_left_wheel_joint_trans">
    <type>transmission_interface/SimpleTransmission</type>
    <joint name="robot_left_wheel_joint">
      <!-- for the gazebo plugin -->
      <!--hardwareInterface>EffortJointInterface</hardwareInterface-->
      <!-- for ros control controller -->
      <hardwareInterface>hardware_interface/VelocityJointInterface</hardwareInterface>
    </joint>
    <actuator name="robot_left_wheel_joint_motor">
      <mechanicalReduction>1</mechanicalReduction>
      <motorTorqueConstant>20</motorTorqueConstant>
    </actuator>
  </transmission>
  <gazebo reference="robot_left_wheel_link">
    <!-- mu1 value="5.0"/>
			<mu2 value="0.5"/>
			<kp value="10000000.0" />
			<kd value="1.0" />
			<fdir1 value="1 0 0"/>
			<material>Gazebo/Yellow</material>
			<turnGravityOff>false</turnGravityOff -->
    <!-- mu1 value="5.0"/>
			<mu2 value="0.5"/ -->
    <mu1 value="100.0"/>
    <mu2 value="100.0"/>
    <!-- kp value="100000.0" / -->
    <kp value="500000.0"/>
    <kd value="1.0"/>
    <!-- fdir1 value="1 0 0"/ -->
    <material>Gazebo/Yellow</material>
    <turnGravityOff>false</turnGravityOff>
    <!--kp>500000.0</kp>
			<kd>10.0</kd>
			<mu1>10</mu1>
			<mu2>10</mu2>
			<fdir1>1 0 0</fdir1-->
    <!--minDepth>0.001</minDepth-->
    <!--material>Gazebo/Black</material-->
    <!--mu1 value="10"/>
			<mu2 value="5"/>
			<kp value="500000.0" />
			<kd value="10.0" />
			<fdir1 value="1 0 0"/>
			<material>Gazebo/Yellow</material>
			<turnGravityOff>false</turnGravityOff-->
  </gazebo>
  <!--gazebo reference="${name}_wheel_link">
			<kp>500000.0</kp>
			<kd>10.0</kd>
			<mu1>10</mu1>
			<mu2>10</mu2>
			<fdir1>1 0 0</fdir1>
			<maxVel>1.0</maxVel>
			<minDepth>0.003</minDepth>
			<material>Gazebo/Yellow</material>
			<turnGravityOff>false</turnGravityOff>
			<implicitSpringDamper>1</implicitSpringDamper>
		</gazebo-->
  <!-- xacro:caster prefix="$(arg prefix)left" parent="$(arg prefix)support" hq="${hq}">
		<origin xyz="${caster_offset_x} ${caster_offset_y} ${caster_offset_z}" rpy="0 0 0"/>
	</xacro:caster -->
  <!--CASTER SUPPORT -->
  <joint name="robot_leftcastorjoint_support" type="continuous">
    <parent link="robot_leftrsupport"/>
    <child link="robot_leftcastorsupport"/>
    <origin rpy="0 0 0" xyz="0.1175 0.01 0.002"/>
    <axis rpy="0 3.14159265359 0" xyz="0 0 1"/>
    <limit effort="100" velocity="100"/>
    <!-- joint_properties damping="1.5" friction="1.5"/ -->
    <dynamics damping="0" friction="0.01"/>
  </joint>
  <link name="robot_leftcastorsupport">
    <visual>
      <origin rpy="0 0 0" xyz="0 0 0"/>
      <geometry>
        <mesh filename="package://rb_theron_description/meshes/wheels/mcq_prototype_base_castor.dae"/>
      </geometry>
    </visual>
    <collision>
      <origin rpy="0 0 0" xyz="0 0 0"/>
      <geometry>
        <mesh filename="package://rb_theron_description/meshes/wheels/mcq_prototype_base_castor.dae"/>
      </geometry>
    </collision>
    <inertial>
      <mass value="1.5"/>
      <origin xyz="0 0 0"/>
      <inertia ixx="5e-05" ixy="0" ixz="0" iyy="5e-05" iyz="0" izz="7.5e-05"/>
      <!--Check these values -->
    </inertial>
  </link>
  <joint name="robot_leftcastorjoint_wheel" type="continuous">
    <parent link="robot_leftcastorsupport"/>
    <child link="robot_leftcastorwheel"/>
    <origin rpy="0 0 0" xyz="-0.033 0.0 -0.071"/>
    <axis rpy="0 0 0" xyz="0 1 0"/>
    <limit effort="100" velocity="100"/>
    <joint_properties damping="0.1" friction="0.1"/>
  </joint>
  <link name="robot_leftcastorwheel">
    <visual>
      <!-- HIGH RESOLUTION WHEELS -->
      <!-- xacro:if value="${hq}">
          <origin xyz="0 0 0" rpy="0 0 0" />
          <geometry>     
		<mesh filename="package://rb_theron_description/meshes/wheels/mcq_prototype_castor_wheel.dae" />
          </geometry>         
        </xacro:if -->
      <!-- LOW RESOLUTION WHEELS -->
      <!-- xacro:unless value="${hq}" -->
      <origin rpy="1.57079632679 0 0" xyz="0 0 0"/>
      <geometry>
        <cylinder length="0.025" radius="0.05"/>
        <!-- sphere radius="${caster_radius}"/ -->
      </geometry>
      <!-- /xacro:unless -->
    </visual>
    <collision>
      <origin rpy="1.57079632679 0 0" xyz="0 0 0"/>
      <!-- origin xyz="0 0 0" rpy="0 0 0" / -->
      <geometry>
        <!-- mesh filename="package://rb_theron_description/meshes/wheels/mcq_prototype_castor_wheel.dae" / -->
        <cylinder length="0.025" radius="0.05"/>
        <!-- sphere radius="${caster_radius}"/ -->
      </geometry>
      <surface>
        <bounce restitution_coefficient="1"/>
      </surface>
    </collision>
    <inertial>
      <mass value="0.25"/>
      <origin xyz="0 0 0"/>
      <inertia ixx="0.000169270833333" ixy="0" ixz="0" iyy="0.000169270833333" iyz="0" izz="0.0003125"/>
    </inertial>
  </link>
  <!-- Transmission is important to link the joints and the controller -->
  <transmission name="robot_leftcastorsupport_joint_trans">
    <type>transmission_interface/SimpleTransmission</type>
    <joint name="robot_leftcastorjoint_support">
      <hardwareInterface>hardware_interface/EffortJointInterface</hardwareInterface>
    </joint>
    <actuator name="robot_leftcastorsupport_joint_motor">
      <mechanicalReduction>1</mechanicalReduction>
      <motorTorqueConstant>1</motorTorqueConstant>
    </actuator>
  </transmission>
  <transmission name="robot_leftcastorwheel_joint_trans">
    <type>transmission_interface/SimpleTransmission</type>
    <joint name="robot_leftcastorjoint_wheel">
      <hardwareInterface>hardware_interface/EffortJointInterface</hardwareInterface>
    </joint>
    <actuator name="robot_leftcastorwheel_joint_motor">
      <mechanicalReduction>1</mechanicalReduction>
      <motorTorqueConstant>1</motorTorqueConstant>
    </actuator>
  </transmission>
  <!-- gazebo reference="${prefix}support">
			<mu1 value="5.0"/>
			<mu2 value="0.5"/>
			<kp value="10000000.0" />
			<kd value="1.0" />
			<fdir1 value="1 0 0"/>
      <turnGravityOff>false</turnGravityOff>
    </gazebo -->
  <gazebo reference="robot_leftcastor_wheel">
    <mu1 value="100.0"/>
    <mu2 value="100.0"/>
    <!-- kp value="10000000.0" / -->
    <kp value="100000.0"/>
    <kd value="100.0"/>
    <!-- fdir1 value="1 0 0"/ -->
    <material>Gazebo/Black</material>
    <turnGravityOff>false</turnGravityOff>
  </gazebo>
  <!-- gazebo reference="${prefix}support">
			<mu1 value="5.0"/>
			<mu2 value="0.5"/>
			<kp value="10000000.0" />
			<kd value="1.0" />
			<fdir1 value="1 0 0"/>
      <turnGravityOff>false</turnGravityOff>
    </gazebo>
    
     <gazebo reference="${prefix}_wheel">
			<mu1 value="5.0"/>
			<mu2 value="0.5"/>
			<kp value="10000000.0" />
			<kd value="1.0" />
			<fdir1 value="1 0 0"/>
      <turnGravityOff>false</turnGravityOff>
    </gazebo -->
  <!--CASTER SUPPORT -->
  <joint name="robot_leftjoint_support" type="continuous">
    <parent link="robot_base_link"/>
    <child link="robot_leftsupport"/>
    <origin rpy="0 0 0" xyz="-0.235 0.1725 0.0428"/>
    <axis rpy="0 3.14159265359 0" xyz="0 0 1"/>
    <limit effort="100" velocity="100"/>
    <!-- joint_properties damping="1.5" friction="1.5"/ -->
    <dynamics damping="0" friction="0.01"/>
  </joint>
  <link name="robot_leftsupport">
    <visual>
      <origin rpy="0 0 0" xyz="0 0 0"/>
      <geometry>
        <mesh filename="package://rb_theron_description/meshes/wheels/mcq_prototype_base_castor.dae"/>
      </geometry>
    </visual>
    <collision>
      <origin rpy="0 0 0" xyz="0 0 0"/>
      <geometry>
        <mesh filename="package://rb_theron_description/meshes/wheels/mcq_prototype_base_castor.dae"/>
      </geometry>
    </collision>
    <inertial>
      <mass value="1.5"/>
      <origin xyz="0 0 0"/>
      <inertia ixx="5e-05" ixy="0" ixz="0" iyy="5e-05" iyz="0" izz="7.5e-05"/>
      <!--Check these values -->
    </inertial>
  </link>
  <joint name="robot_leftjoint_wheel" type="continuous">
    <parent link="robot_leftsupport"/>
    <child link="robot_leftwheel"/>
    <origin rpy="0 0 0" xyz="-0.033 0.0 -0.071"/>
    <axis rpy="0 0 0" xyz="0 1 0"/>
    <limit effort="100" velocity="100"/>
    <joint_properties damping="0.1" friction="0.1"/>
  </joint>
  <link name="robot_leftwheel">
    <visual>
      <!-- HIGH RESOLUTION WHEELS -->
      <!-- xacro:if value="${hq}">
          <origin xyz="0 0 0" rpy="0 0 0" />
          <geometry>     
		<mesh filename="package://rb_theron_description/meshes/wheels/mcq_prototype_castor_wheel.dae" />
          </geometry>         
        </xacro:if -->
      <!-- LOW RESOLUTION WHEELS -->
      <!-- xacro:unless value="${hq}" -->
      <origin rpy="1.57079632679 0 0" xyz="0 0 0"/>
      <geometry>
        <cylinder length="0.025" radius="0.05"/>
        <!-- sphere radius="${caster_radius}"/ -->
      </geometry>
      <!-- /xacro:unless -->
    </visual>
    <collision>
      <origin rpy="1.57079632679 0 0" xyz="0 0 0"/>
      <!-- origin xyz="0 0 0" rpy="0 0 0" / -->
      <geometry>
        <!-- mesh filename="package://rb_theron_description/meshes/wheels/mcq_prototype_castor_wheel.dae" / -->
        <cylinder length="0.025" radius="0.05"/>
        <!-- sphere radius="${caster_radius}"/ -->
      </geometry>
      <surface>
        <bounce restitution_coefficient="1"/>
      </surface>
    </collision>
    <inertial>
      <mass value="0.25"/>
      <origin xyz="0 0 0"/>
      <inertia ixx="0.000169270833333" ixy="0" ixz="0" iyy="0.000169270833333" iyz="0" izz="0.0003125"/>
    </inertial>
  </link>
  <!-- Transmission is important to link the joints and the controller -->
  <transmission name="robot_leftsupport_joint_trans">
    <type>transmission_interface/SimpleTransmission</type>
    <joint name="robot_leftjoint_support">
      <hardwareInterface>hardware_interface/EffortJointInterface</hardwareInterface>
    </joint>
    <actuator name="robot_leftsupport_joint_motor">
      <mechanicalReduction>1</mechanicalReduction>
      <motorTorqueConstant>1</motorTorqueConstant>
    </actuator>
  </transmission>
  <transmission name="robot_leftwheel_joint_trans">
    <type>transmission_interface/SimpleTransmission</type>
    <joint name="robot_leftjoint_wheel">
      <hardwareInterface>hardware_interface/EffortJointInterface</hardwareInterface>
    </joint>
    <actuator name="robot_leftwheel_joint_motor">
      <mechanicalReduction>1</mechanicalReduction>
      <motorTorqueConstant>1</motorTorqueConstant>
    </actuator>
  </transmission>
  <!-- gazebo reference="${prefix}support">
			<mu1 value="5.0"/>
			<mu2 value="0.5"/>
			<kp value="10000000.0" />
			<kd value="1.0" />
			<fdir1 value="1 0 0"/>
      <turnGravityOff>false</turnGravityOff>
    </gazebo -->
  <gazebo reference="robot_left_wheel">
    <mu1 value="100.0"/>
    <mu2 value="100.0"/>
    <!-- kp value="10000000.0" / -->
    <kp value="100000.0"/>
    <kd value="100.0"/>
    <!-- fdir1 value="1 0 0"/ -->
    <material>Gazebo/Black</material>
    <turnGravityOff>false</turnGravityOff>
  </gazebo>
  <!--CASTER SUPPORT -->
  <joint name="robot_rightjoint_support" type="continuous">
    <parent link="robot_base_link"/>
    <child link="robot_rightsupport"/>
    <origin rpy="0 0 0" xyz="-0.235 -0.1725 0.0428"/>
    <axis rpy="0 3.14159265359 0" xyz="0 0 1"/>
    <limit effort="100" velocity="100"/>
    <!-- joint_properties damping="1.5" friction="1.5"/ -->
    <dynamics damping="0" friction="0.01"/>
  </joint>
  <link name="robot_rightsupport">
    <visual>
      <origin rpy="0 0 0" xyz="0 0 0"/>
      <geometry>
        <mesh filename="package://rb_theron_description/meshes/wheels/mcq_prototype_base_castor.dae"/>
      </geometry>
    </visual>
    <collision>
      <origin rpy="0 0 0" xyz="0 0 0"/>
      <geometry>
        <mesh filename="package://rb_theron_description/meshes/wheels/mcq_prototype_base_castor.dae"/>
      </geometry>
    </collision>
    <inertial>
      <mass value="1.5"/>
      <origin xyz="0 0 0"/>
      <inertia ixx="5e-05" ixy="0" ixz="0" iyy="5e-05" iyz="0" izz="7.5e-05"/>
      <!--Check these values -->
    </inertial>
  </link>
  <joint name="robot_rightjoint_wheel" type="continuous">
    <parent link="robot_rightsupport"/>
    <child link="robot_rightwheel"/>
    <origin rpy="0 0 0" xyz="-0.033 0.0 -0.071"/>
    <axis rpy="0 0 0" xyz="0 1 0"/>
    <limit effort="100" velocity="100"/>
    <joint_properties damping="0.1" friction="0.1"/>
  </joint>
  <link name="robot_rightwheel">
    <visual>
      <!-- HIGH RESOLUTION WHEELS -->
      <!-- xacro:if value="${hq}">
          <origin xyz="0 0 0" rpy="0 0 0" />
          <geometry>     
		<mesh filename="package://rb_theron_description/meshes/wheels/mcq_prototype_castor_wheel.dae" />
          </geometry>         
        </xacro:if -->
      <!-- LOW RESOLUTION WHEELS -->
      <!-- xacro:unless value="${hq}" -->
      <origin rpy="1.57079632679 0 0" xyz="0 0 0"/>
      <geometry>
        <cylinder length="0.025" radius="0.05"/>
        <!-- sphere radius="${caster_radius}"/ -->
      </geometry>
      <!-- /xacro:unless -->
    </visual>
    <collision>
      <origin rpy="1.57079632679 0 0" xyz="0 0 0"/>
      <!-- origin xyz="0 0 0" rpy="0 0 0" / -->
      <geometry>
        <!-- mesh filename="package://rb_theron_description/meshes/wheels/mcq_prototype_castor_wheel.dae" / -->
        <cylinder length="0.025" radius="0.05"/>
        <!-- sphere radius="${caster_radius}"/ -->
      </geometry>
      <surface>
        <bounce restitution_coefficient="1"/>
      </surface>
    </collision>
    <inertial>
      <mass value="0.25"/>
      <origin xyz="0 0 0"/>
      <inertia ixx="0.000169270833333" ixy="0" ixz="0" iyy="0.000169270833333" iyz="0" izz="0.0003125"/>
    </inertial>
  </link>
  <!-- Transmission is important to link the joints and the controller -->
  <transmission name="robot_rightsupport_joint_trans">
    <type>transmission_interface/SimpleTransmission</type>
    <joint name="robot_rightjoint_support">
      <hardwareInterface>hardware_interface/EffortJointInterface</hardwareInterface>
    </joint>
    <actuator name="robot_rightsupport_joint_motor">
      <mechanicalReduction>1</mechanicalReduction>
      <motorTorqueConstant>1</motorTorqueConstant>
    </actuator>
  </transmission>
  <transmission name="robot_rightwheel_joint_trans">
    <type>transmission_interface/SimpleTransmission</type>
    <joint name="robot_rightjoint_wheel">
      <hardwareInterface>hardware_interface/EffortJointInterface</hardwareInterface>
    </joint>
    <actuator name="robot_rightwheel_joint_motor">
      <mechanicalReduction>1</mechanicalReduction>
      <motorTorqueConstant>1</motorTorqueConstant>
    </actuator>
  </transmission>
  <!-- gazebo reference="${prefix}support">
			<mu1 value="5.0"/>
			<mu2 value="0.5"/>
			<kp value="10000000.0" />
			<kd value="1.0" />
			<fdir1 value="1 0 0"/>
      <turnGravityOff>false</turnGravityOff>
    </gazebo -->
  <gazebo reference="robot_right_wheel">
    <mu1 value="100.0"/>
    <mu2 value="100.0"/>
    <!-- kp value="10000000.0" / -->
    <kp value="100000.0"/>
    <kd value="100.0"/>
    <!-- fdir1 value="1 0 0"/ -->
    <material>Gazebo/Black</material>
    <turnGravityOff>false</turnGravityOff>
  </gazebo>
  <joint name="robot_pole_joint" type="fixed">
    <parent link="robot_base_link"/>
    <child link="robot_pole_link"/>
    <origin rpy="0 0 0" xyz="0.0 0.0 0.2208"/>
  </joint>
  <!-- BASE_LINK -->
  <link name="robot_pole_link">
    <inertial>
      <mass value="10.0"/>
      <origin xyz="0 0 0"/>
      <inertia ixx="2.05416666667" ixy="0" ixz="0" iyy="2.05416666667" iyz="0" izz="2.05416666667"/>
    </inertial>
    <visual>
      <origin rpy="0 0 0" xyz="0 0 0"/>
      <!-- in this case change origin -->
      <geometry>
        <!-- <box size="0.25 0.25 1.55"/> -->
        <mesh filename="package://rb_theron_description/meshes/pole/mcq_pole.stl"/>
      </geometry>
      <material name="darkgrey">
        <color rgba="0.1 0.1 0.1 1"/>
      </material>
    </visual>
    <collision>
      <origin rpy="0 0 0 " xyz="0 0 0"/>
      <geometry>
        <!-- <box size="0.25 0.25 1.55"/> -->
        <mesh filename="package://rb_theron_description/meshes/pole/mcq_pole.stl"/>
      </geometry>
    </collision>
  </link>
  <gazebo reference="robot_pole_link">
    <mu1 value="100.0"/>
    <mu2 value="100.0"/>
    <kp value="500000.0"/>
    <kd value="1.0"/>
    <material>Gazebo/Yellow</material>
    <turnGravityOff>false</turnGravityOff>
    <!--kp>500000.0</kp>
			<kd>10.0</kd>
			<mu1>10</mu1>
			<mu2>10</mu2>
			<fdir1>1 0 0</fdir1-->
    <!--minDepth>0.001</minDepth-->
    <!--material>Gazebo/Black</material-->
    <!--mu1 value="10"/>
			<mu2 value="5"/>
			<kp value="500000.0" />
			<kd value="10.0" />
			<fdir1 value="1 0 0"/>
			<material>Gazebo/Yellow</material>
			<turnGravityOff>false</turnGravityOff-->
  </gazebo>
  <!-- camera body, with origin at bottom screw mount -->
  <joint name="robot_front_realsense_camera_camera_joint" type="fixed">
    <origin rpy="0 0 0" xyz="0.3305 0.0 0.1468"/>
    <parent link="robot_base_link"/>
    <child link="robot_front_realsense_camera_camera_link"/>
  </joint>
  <link name="robot_front_realsense_camera_camera_link">
    <visual>
      <!-- origin xyz="0 ${-r430_cam_mount_from_center_offset} ${r430_cam_height/2}" rpy="${M_PI/2} 0 ${M_PI/2}"/ -->
      <origin rpy="0 0 0" xyz="0 -0.0 0"/>
      <geometry>
        <!-- box size="${r430_cam_width} ${r430_cam_height} ${r430_cam_depth}"/ -->
        <mesh filename="package://robotnik_sensors/meshes/intel_r430.dae"/>
      </geometry>
      <material name="aluminum">
        <color rgba="0.5 0.5 0.5 1"/>
      </material>
    </visual>
    <collision>
      <origin rpy="0 0 0" xyz="-0.0125 0.0 0.0"/>
      <geometry>
        <box size="0.025 0.1 0.025"/>
      </geometry>
    </collision>
    <inertial>
      <origin rpy="0 0 0" xyz="-0.0125 0.0 0.0"/>
      <mass value="0.1"/>
      <inertia ixx="7.27083333333e-05" ixy="0" ixz="0" iyy="1.04166666667e-05" iyz="0" izz="7.27083333333e-05"/>
    </inertial>
  </link>
  <!-- camera depth joints and links -->
  <joint name="robot_front_realsense_camera_camera_depth_joint" type="fixed">
    <origin rpy="0 0 0" xyz="0.0 -0.0115 0.0"/>
    <parent link="robot_front_realsense_camera_camera_link"/>
    <child link="robot_front_realsense_camera_camera_depth_frame"/>
  </joint>
  <link name="robot_front_realsense_camera_camera_depth_frame"/>
  <joint name="robot_front_realsense_camera_camera_depth_optical_joint" type="fixed">
    <origin rpy="-1.57079632679 0 -1.57079632679" xyz="0 0 0"/>
    <parent link="robot_front_realsense_camera_camera_depth_frame"/>
    <child link="robot_front_realsense_camera_camera_depth_optical_frame"/>
  </joint>
  <link name="robot_front_realsense_camera_camera_depth_optical_frame"/>
  <!-- camera left IR joints and links -->
  <joint name="robot_front_realsense_camera_camera_left_ir_joint" type="fixed">
    <origin rpy="0 0 0" xyz="0 -0.021 0"/>
    <parent link="robot_front_realsense_camera_camera_depth_frame"/>
    <child link="robot_front_realsense_camera_camera_left_ir_frame"/>
  </joint>
  <link name="robot_front_realsense_camera_camera_left_ir_frame"/>
  <joint name="robot_front_realsense_camera_camera_left_ir_optical_joint" type="fixed">
    <origin rpy="-1.57079632679 0 -1.57079632679" xyz="0 0 0"/>
    <parent link="robot_front_realsense_camera_camera_left_ir_frame"/>
    <child link="robot_front_realsense_camera_camera_left_ir_optical_frame"/>
  </joint>
  <link name="robot_front_realsense_camera_camera_left_ir_optical_frame"/>
  <!-- camera right IR joints and links -->
  <joint name="robot_front_realsense_camera_camera_right_ir_joint" type="fixed">
    <origin rpy="0 0 0" xyz="0 0.029 0"/>
    <parent link="robot_front_realsense_camera_camera_depth_frame"/>
    <child link="robot_front_realsense_camera_camera_right_ir_frame"/>
  </joint>
  <link name="robot_front_realsense_camera_camera_right_ir_frame"/>
  <joint name="robot_front_realsense_camera_camera_right_ir_optical_joint" type="fixed">
    <origin rpy="-1.57079632679 0 -1.57079632679" xyz="0 0 0"/>
    <parent link="robot_front_realsense_camera_camera_right_ir_frame"/>
    <child link="robot_front_realsense_camera_camera_right_ir_optical_frame"/>
  </joint>
  <link name="robot_front_realsense_camera_camera_right_ir_optical_frame"/>
  <!-- camera fisheye joints and links -->
  <joint name="robot_front_realsense_camera_camera_fisheye_joint" type="fixed">
    <origin rpy="0 0 0" xyz="0 0.044 0"/>
    <parent link="robot_front_realsense_camera_camera_depth_frame"/>
    <child link="robot_front_realsense_camera_camera_fisheye_frame"/>
  </joint>
  <link name="robot_front_realsense_camera_camera_fisheye_frame"/>
  <joint name="robot_front_realsense_camera_camera_fisheye_optical_joint" type="fixed">
    <origin rpy="-1.57079632679 0 -1.57079632679" xyz="0 0 0"/>
    <parent link="robot_front_realsense_camera_camera_fisheye_frame"/>
    <child link="robot_front_realsense_camera_camera_fisheye_optical_frame"/>
  </joint>
  <link name="robot_front_realsense_camera_camera_fisheye_optical_frame"/>
  <!-- gazebo reference="${prefix}_rgb_base_link" -->
  <gazebo reference="robot_front_realsense_camera_camera_link">
    <sensor name="robot_front_realsense_camera_depth_sensor" type="depth">
      <always_on>true</always_on>
      <update_rate>15.0</update_rate>
      <camera>
        <horizontal_fov>1.59174027782</horizontal_fov>
        <image>
          <format>R8G8B8</format>
          <width>640</width>
          <height>480</height>
        </image>
        <clip>
          <near>0.3</near>
          <far>10.0</far>
        </clip>
      </camera>
      <plugin filename="libgazebo_ros_openni_kinect.so" name="robot_front_realsense_camera_controller">
        <cameraName>front_realsense_camera</cameraName>
        <alwaysOn>true</alwaysOn>
        <updateRate>10</updateRate>
        <imageTopicName>rgb/image_raw</imageTopicName>
        <depthImageTopicName>depth/image_raw</depthImageTopicName>
        <pointCloudTopicName>depth/points</pointCloudTopicName>
        <cameraInfoTopicName>rgb/camera_info</cameraInfoTopicName>
        <depthImageCameraInfoTopicName>depth/camera_info</depthImageCameraInfoTopicName>
        <frameName>/robot_front_realsense_camera_camera_depth_optical_frame</frameName>
        <baseline>0.1</baseline>
        <distortion_k1>0.0</distortion_k1>
        <distortion_k2>0.0</distortion_k2>
        <distortion_k3>0.0</distortion_k3>
        <distortion_t1>0.0</distortion_t1>
        <distortion_t2>0.0</distortion_t2>
        <pointCloudCutoff>0.4</pointCloudCutoff>
      </plugin>
    </sensor>
  </gazebo>
  <joint name="robot_front_rgbd_camera_joint" type="fixed">
    <origin rpy="0 0 0" xyz="0.3305 0.0 0.1898"/>
    <parent link="robot_base_link"/>
    <child link="robot_front_rgbd_camera_link"/>
  </joint>
  <link name="robot_front_rgbd_camera_link">
    <visual>
      <origin rpy="0 0 0" xyz="0 0 0"/>
      <geometry>
        <mesh filename="package://robotnik_sensors/meshes/orbbec_astra.dae"/>
      </geometry>
    </visual>
    <collision>
      <geometry>
        <mesh filename="package://robotnik_sensors/meshes/orbbec_astra.dae"/>
      </geometry>
    </collision>
    <inertial>
      <mass value="0.001"/>
      <origin xyz="0.0 0.0 0.0"/>
      <inertia ixx="2.34375e-06" ixy="0" ixz="0" iyy="2.08333333333e-07" iyz="0" izz="2.40208333333e-06"/>
    </inertial>
  </link>
  <joint name="robot_front_rgbd_camera_rgb_joint" type="fixed">
    <origin rpy="0.0 0.0 0.0" xyz="0.0 0.0125 0.0150"/>
    <parent link="robot_front_rgbd_camera_link"/>
    <child link="robot_front_rgbd_camera_rgb_frame"/>
  </joint>
  <link name="robot_front_rgbd_camera_rgb_frame">
    <inertial>
      <mass value="0.297"/>
      <origin xyz="-0.02 -0.0125 0.0"/>
      <inertia ixx="0.00069609375" ixy="0" ixz="0" iyy="6.1875e-05" iyz="0" izz="0.00071341875"/>
    </inertial>
  </link>
  <joint name="robot_front_rgbd_camera_rgb_optical_joint" type="fixed">
    <origin rpy="-1.57079632679 0 -1.57079632679" xyz="0.0 0.0 0.0"/>
    <parent link="robot_front_rgbd_camera_rgb_frame"/>
    <child link="robot_front_rgbd_camera_rgb_optical_frame"/>
  </joint>
  <link name="robot_front_rgbd_camera_rgb_optical_frame">
    <inertial>
      <mass value="0.001"/>
      <origin rpy="1.57079632679 0 1.57079632679" xyz="0 0 0"/>
      <inertia ixx="2.34375e-06" ixy="0" ixz="0" iyy="2.08333333333e-07" iyz="0" izz="2.40208333333e-06"/>
    </inertial>
  </link>
  <joint name="robot_front_rgbd_camera_depth_joint" type="fixed">
    <origin rpy="0 0 0" xyz="0.0 0.0375 0.0150"/>
    <parent link="robot_front_rgbd_camera_link"/>
    <child link="robot_front_rgbd_camera_depth_frame"/>
  </joint>
  <link name="robot_front_rgbd_camera_depth_frame">
    <inertial>
      <mass value="0.001"/>
      <origin xyz="0 0 0"/>
      <inertia ixx="2.34375e-06" ixy="0" ixz="0" iyy="2.08333333333e-07" iyz="0" izz="2.40208333333e-06"/>
    </inertial>
  </link>
  <joint name="robot_front_rgbd_camera_depth_optical_joint" type="fixed">
    <origin rpy="-1.57079632679 0 -1.57079632679" xyz="0 0 0"/>
    <parent link="robot_front_rgbd_camera_depth_frame"/>
    <child link="robot_front_rgbd_camera_depth_optical_frame"/>
  </joint>
  <link name="robot_front_rgbd_camera_depth_optical_frame">
    <inertial>
      <mass value="0.001"/>
      <origin xyz="0 0 0"/>
      <inertia ixx="2.34375e-06" ixy="0" ixz="0" iyy="2.08333333333e-07" iyz="0" izz="2.40208333333e-06"/>
    </inertial>
  </link>
  <gazebo reference="robot_front_rgbd_camera_link">
    <sensor name="robot_front_rgbd_camera_depth_sensor" type="depth">
      <always_on>true</always_on>
      <update_rate>20.0</update_rate>
      <camera>
        <horizontal_fov>1.0471975512</horizontal_fov>
        <image>
          <format>R8G8B8</format>
          <width>640</width>
          <height>480</height>
        </image>
        <clip>
          <near>0.05</near>
          <far>3.5</far>
        </clip>
      </camera>
      <plugin filename="libgazebo_ros_openni_kinect.so" name="robot_front_rgbd_camera_controller">
        <cameraName>front_rgbd_camera</cameraName>
        <alwaysOn>true</alwaysOn>
        <updateRate>10</updateRate>
        <imageTopicName>rgb/image_raw</imageTopicName>
        <depthImageTopicName>depth/image_raw</depthImageTopicName>
        <pointCloudTopicName>depth/points</pointCloudTopicName>
        <cameraInfoTopicName>rgb/camera_info</cameraInfoTopicName>
        <depthImageCameraInfoTopicName>depth/camera_info</depthImageCameraInfoTopicName>
        <frameName>/robot_front_rgbd_camera_depth_optical_frame</frameName>
        <baseline>0.1</baseline>
        <distortion_k1>0.0</distortion_k1>
        <distortion_k2>0.0</distortion_k2>
        <distortion_k3>0.0</distortion_k3>
        <distortion_t1>0.0</distortion_t1>
        <distortion_t2>0.0</distortion_t2>
        <pointCloudCutoff>0.4</pointCloudCutoff>
      </plugin>
    </sensor>
  </gazebo>
  <joint name="robot_imu_joint" type="fixed">
    <axis xyz="1 0 0"/>
    <!--origin xyz="0 0 0.2825"/-->
    <origin rpy="0 0 0" xyz="-0.1975 0.0 0.1598"/>
    <parent link="robot_base_link"/>
    <child link="robot_imu_link"/>
  </joint>
  <link name="robot_imu_link">
    <inertial>
      <origin rpy="0 0 0" xyz="0.0 0 0.01"/>
      <mass value="0.05"/>
      <inertia ixx="3.33333333333e-06" ixy="0" ixz="0" iyy="3.33333333333e-06" iyz="0" izz="3.33333333333e-06"/>
    </inertial>
    <visual>
      <origin rpy="0 0 0" xyz="0 0 0"/>
      <geometry>
        <box size="0.001 0.001 0.001"/>
      </geometry>
    </visual>
    <collision>
      <origin rpy="0 0 0" xyz="0 0 0"/>
      <geometry>
        <box size=".001 .001 .001"/>
      </geometry>
    </collision>
  </link>
  <gazebo>
    <plugin filename="libhector_gazebo_ros_imu.so" name="robot_imu_controller">
      <alwaysOn>true</alwaysOn>
      <topicName>imu/data</topicName>
      <serviceName>robot_imuimu/service</serviceName>
      <bodyName>robot_imu_link</bodyName>
      <frameId>robot_imu_link</frameId>
      <updateRate>50.0</updateRate>
      <gaussianNoise>0.00</gaussianNoise>
      <yawOffset>0.0</yawOffset>
      <yawDrift>0.0</yawDrift>
      <yawGaussianNoise>0.0</yawGaussianNoise>
      <!-- angular velocities parameters -->
      <rateOffset>0.0 0.0 0.0</rateOffset>
      <rateDrift>0.0 0.0 0.0</rateDrift>
      <rateGaussianNoise>0.0 0.0 0.0</rateGaussianNoise>
      <!-- linear accelerations parameters -->
      <accelOffset>0.0 0.0 0.0</accelOffset>
      <accelDrift>0.0 0.0 0.0</accelDrift>
      <accelGaussianNoise>0.0 0.0 0.0</accelGaussianNoise>
    </plugin>
  </gazebo>
  <joint name="robot_lidar_3d_base_joint" type="fixed">
    <origin rpy="0 -1.5707 3.1416" xyz="0.132 0.0 1.003"/>
    <parent link="robot_pole_link"/>
    <child link="robot_lidar_3d_base_link"/>
  </joint>
  <link name="robot_lidar_3d_base_link">
    <visual>
      <!-- origin xyz="0 0 0" rpy="0 0 1.5708"/ -->
      <origin rpy="0 0 0" xyz="0 0 0"/>
      <geometry>
        <mesh filename="package://robotnik_sensors/meshes/rs_bpearl.stl"/>
      </geometry>
      <material name="blackgray_color">
        <color rgba="0.25 0.25 0.25 1"/>
      </material>
    </visual>
    <collision>
      <origin rpy="0 0 0" xyz="0 0 0"/>
      <geometry>
        <mesh filename="package://robotnik_sensors/meshes/rs_bpearl.stl"/>
      </geometry>
    </collision>
    <inertial>
      <!-- The following are not reliable values, and should not be used for modeling -->
      <mass value="0.92"/>
      <origin xyz="0 0 0.055"/>
      <inertia ixx="0.00187227666667" ixy="0" ixz="0" iyy="0.00187227666667" iyz="0" izz="0.00188922"/>
    </inertial>
  </link>
  <joint name="robot_lidar_3d_joint" type="fixed">
    <parent link="robot_lidar_3d_base_link"/>
    <child link="robot_lidar_3d_link"/>
    <origin rpy="0 0 0" xyz="0 0 0.09427"/>
  </joint>
  <link name="robot_lidar_3d_link"/>
  <gazebo reference="robot_lidar_3d_base_link">
    <visual>
      <material>
        <ambient>0.5 0.5 0.5 1.0</ambient>
        <diffuse>0.250754 0.250754 0.250754 1.0</diffuse>
        <specular>0.2508273 0.2508273 0.2508273 1.0</specular>
        <emissive>0.0 0.0 0.0 0.0</emissive>
      </material>
    </visual>
  </gazebo>
  <gazebo reference="robot_lidar_3d_link">
    <visual>
      <material>
        <ambient>1.2 0.2 0.2 1.0</ambient>
        <diffuse>0.250754 0.250754 0.250754 1.0</diffuse>
        <specular>0.2508273 0.2508273 0.2508273 1.0</specular>
        <emissive>0.0 0.0 0.0 0.0</emissive>
      </material>
    </visual>
    <sensor name="robot_lidar_3d_sensor" type="gpu_ray">
      <pose>0 0 0 0 0 0.0</pose>
      <visualize>false</visualize>
      <update_rate>20.0</update_rate>
      <ray>
        <scan>
          <horizontal>
            <!-- for a high quality simulation -->
            <samples>900</samples>
            <min_angle>-3.14159265359</min_angle>
            <max_angle>3.14159265359</max_angle>
          </horizontal>
          <vertical>
            <samples>32</samples>
            <min_angle>-0.0872664625997</min_angle>
            <!-- bpearl has 90 degrees of vertical field of view-->
            <max_angle> 1.4835298642</max_angle>
          </vertical>
        </scan>
        <range>
          <min>0.1</min>
          <max>30.0</max>
          <resolution>0.01</resolution>
        </range>
        <noise>
          <type>none</type>
        </noise>
      </ray>
      <plugin filename="libgazebo_ros_velodyne_gpu_laser.so" name="robot_lidar_3d_controller">
        <topicName>lidar_3d/points</topicName>
        <frameName>/robot_lidar_3d_link</frameName>
        <gaussianNoise>0.008</gaussianNoise>
      </plugin>
    </sensor>
  </gazebo>
  <joint name="robot_front_laser_base_joint" type="fixed">
    <origin rpy="0 3.1416 3.1416" xyz="0.250 0.0 0.1643"/>
    <parent link="robot_base_link"/>
    <child link="robot_front_laser_base_link"/>
  </joint>
  <link name="robot_front_laser_base_link">
    <collision>
      <origin rpy="0 0 0" xyz="0 0 0"/>
      <geometry>
        <!--<box size="0.106 0.094 0.152"/>-->
        <!--<cylinder radius="0.058" length="0.152"/>-->
        <mesh filename="package://robotnik_sensors/meshes/sick_nanoscan3.stl"/>
      </geometry>
    </collision>
    <visual>
      <origin rpy="0 0 0" xyz="0 0 0"/>
      <geometry>
        <mesh filename="package://robotnik_sensors/meshes/sick_nanoscan3.stl"/>
      </geometry>
    </visual>
    <inertial>
      <mass value="0.67"/>
      <origin rpy="0 0 0" xyz="0 0 0.04"/>
      <inertia ixx="0.000922386766667" ixy="0" ixz="0" iyy="0.000922386766667" iyz="0" izz="0.00113010686667"/>
      <!-- Datasheet dimensional drawing: 100.6 mm x 100.6 mm x 80 mm without connectors -->
    </inertial>
  </link>
  <joint name="robot_front_laser_joint" type="fixed">
    <parent link="robot_front_laser_base_link"/>
    <child link="robot_front_laser_link"/>
    <origin rpy="0 0 0" xyz="0.0 0 0.0505"/>
  </joint>
  <link name="robot_front_laser_link"/>
  <gazebo reference="robot_front_laser_link">
    <sensor name="robot_front_laser_sensor" type="gpu_ray">
      <pose>0 0 0 0 0 0</pose>
      <visualize>false</visualize>
      <update_rate>12.5</update_rate>
      <ray>
        <scan>
          <horizontal>
            <samples>1618</samples>
            <resolution>1</resolution>
            <min_angle>-2.0507619</min_angle>
            <max_angle>2.0507619</max_angle>
          </horizontal>
        </scan>
        <range>
          <min>0.065</min>
          <max>40.0</max>
          <!-- 3m protective, 10 warning, 40 measurement -->
          <resolution>0.07</resolution>
          <!-- Resolution is configurable 20 mm 30 mm 40 mm 50 mm 60 mm 70 mm 150 mm 200 mm, reglamentary resolution is 70 mm -->
        </range>
        <noise>
          <type>gaussian</type>
          <mean>0.0</mean>
          <stddev>0.03</stddev>
        </noise>
      </ray>
      <plugin filename="libgazebo_ros_gpu_laser.so" name="robot_front_laser_controller">
        <topicName>front_laser/scan</topicName>
        <frameName>/robot_front_laser_link</frameName>
        <!-- if not global (leading /) sets the current namespace as a prefix (/ns/name_laser_link) -->
      </plugin>
    </sensor>
  </gazebo>
</robot>
